I'm sorry, but an uncaught exception occurred.

While running game code:
  File "game/ending/endingsFirstTry.rpy", line 63, in script
    show sansImg hoddie worried at face with dissolve:
  File "game/ending/endingsFirstTry.rpy", line 63, in <module>
    show sansImg hoddie worried at face with dissolve:
NameError: name 'face' is not defined

-- Full Traceback ------------------------------------------------------------

Full traceback:
  File "game/ending/endingsFirstTry.rpy", line 63, in script
    show sansImg hoddie worried at face with dissolve:
  File "C:\Users\satel\Downloads\renpy-6.99.12.2-sdk\renpy\ast.py", line 1169, in execute
    show_imspec(self.imspec, atl=getattr(self, "atl", None))
  File "C:\Users\satel\Downloads\renpy-6.99.12.2-sdk\renpy\ast.py", line 1128, in show_imspec
    at_list = [ renpy.python.py_eval(i) for i in at_list ]
  File "C:\Users\satel\Downloads\renpy-6.99.12.2-sdk\renpy\python.py", line 1961, in py_eval
    return py_eval_bytecode(code, globals, locals)
  File "C:\Users\satel\Downloads\renpy-6.99.12.2-sdk\renpy\python.py", line 1954, in py_eval_bytecode
    return eval(bytecode, globals, locals)
  File "game/ending/endingsFirstTry.rpy", line 63, in <module>
    show sansImg hoddie worried at face with dissolve:
NameError: name 'face' is not defined

Windows-8-6.2.9200
Ren'Py 7.2.2.491
User Interface 0.2
Wed Jul 03 22:33:28 2019
