I'm sorry, but an uncaught exception occurred.

While running game code:
  File "game/day3.rpy", line 12, in script call
    call backNewerHome from _call_backNewerHome
  File "game/day3/backHome.rpy", line 389, in script
    sans "i actually surprised myself"
TypeError: 'NoneType' object is not iterable

-- Full Traceback ------------------------------------------------------------

Full traceback:
  File "game/day3.rpy", line 12, in script call
    call backNewerHome from _call_backNewerHome
  File "game/day3/backHome.rpy", line 389, in script
    sans "i actually surprised myself"
  File "C:\Users\satel\Desktop\renpy-7.3.5-sdk\renpy\ast.py", line 708, in execute
    renpy.exports.say(who, what, *args, **kwargs)
  File "C:\Users\satel\Desktop\renpy-7.3.5-sdk\renpy\exports.py", line 1340, in say
    args, kwargs = renpy.config.say_arguments_callback(who, *args, **kwargs)
TypeError: 'NoneType' object is not iterable

Windows-8-6.2.9200
Ren'Py 7.3.5.606
User Interface 0.3
Mon Nov 11 22:54:37 2019
